<?xml version="1.0"?>
<robot xmlns:xacro="http://www.ros.org/wiki/xacro" name="xeno_urdf">

  <link
    name="base_link">
    <inertial>
      <origin
        xyz="0.257617697833826 -0.241929178057704 0.0359105643680267"
        rpy="0 0 0" />
      <mass
        value="3.01621364315181" />
      <inertia
        ixx="0.0266548937293535"
        ixy="0.000163341062609396"
        ixz="3.25666768339596E-05"
        iyy="0.0368562759579921"
        iyz="1.26675265566117E-09"
        izz="0.0336745094167916" />
    </inertial>
    <visual>
      <origin
        xyz="0 0 0"
        rpy="0 0 0" />
      <geometry>
        <mesh
          filename="package://xeno_urdf/xeno_urdf/meshes/base_link.STL" />
      </geometry>
      <material
        name="">
        <color
          rgba="0.79216 0.81961 0.93333 1" />
      </material>
    </visual>
    <collision>
      <origin
        xyz="0 0 0"
        rpy="0 0 0" />
      <geometry>
        <mesh
          filename="package://xeno_urdf/xeno_urdf/meshes/base_link.STL" />
      </geometry>
    </collision>
  </link>

  <link
    name="link_1">
    <inertial>
      <origin
        xyz="0.185028595993171 -0.00832277384304777 -0.178922873539318"
        rpy="0 0 0" />
      <mass
        value="0.331227493236693" />
      <inertia
        ixx="0.00359557900980095"
        ixy="8.1925548911876E-13"
        ixz="4.00969466248576E-18"
        iyy="0.00357618701291859"
        iyz="6.10954129419386E-18"
        izz="6.20714942709694E-05" />
    </inertial>
    <visual>
      <origin
        xyz="0 0 0"
        rpy="0 0 0" />
      <geometry>
        <mesh
          filename="package://xeno_urdf/xeno_urdf/meshes/link_1.STL" />
      </geometry>
      <material
        name="">
        <color
          rgba="0.792156862745098 0.819607843137255 0.933333333333333 1" />
      </material>
    </visual>
    <collision>
      <origin
        xyz="0 0 0"
        rpy="0 0 0" />
      <geometry>
        <mesh
          filename="package://xeno_urdf/xeno_urdf/meshes/link_1.STL" />
      </geometry>
    </collision>
  </link>

  <joint
    name="joint_1"
    type="prismatic">
    <origin
      xyz="0.067202 -0.055049 0.04839"
      rpy="1.5708 0 -1.5708" />
    <parent
      link="base_link" />
    <child
      link="link_1" />
    <axis
      xyz="0 1 0" />
    <!-- 298.37mm -->
    <limit
      lower="0"
      upper="0.29"
      effort="0"
      velocity="1.5" />
  </joint>

  <link
    name="link_2">
    <inertial>
      <origin
        xyz="-0.148042239006251 0.00759459886852325 0.0986119022246263"
        rpy="0 0 0" />
      <mass
        value="1.24451041724569" />
      <inertia
        ixx="0.0083397740074051"
        ixy="-4.12234597309896E-08"
        ixz="1.75114942535788E-06"
        iyy="0.014757742265705"
        iyz="-8.57774520700305E-07"
        izz="0.00653624565374476" />
    </inertial>
    <visual>
      <origin
        xyz="0 0 0"
        rpy="0 0 0" />
      <geometry>
        <mesh
          filename="package://xeno_urdf/xeno_urdf/meshes/link_2.STL" />
      </geometry>
      <material
        name="">
        <color
          rgba="0.792156862745098 0.819607843137255 0.933333333333333 1" />
      </material>
    </visual>
    <collision>
      <origin
        xyz="0 0 0"
        rpy="0 0 0" />
      <geometry>
        <mesh
          filename="package://xeno_urdf/xeno_urdf/meshes/link_2.STL" />
      </geometry>
    </collision>
  </link>
  <!-- 298.37mm -->
  <joint
    name="joint_2"
    type="prismatic">
    <origin
      xyz="0.034 2.4196E-05 0.019096"
      rpy="-3.141 0 3.1416" />
    <parent
      link="link_1" />
    <child
      link="link_2" />
    <axis
      xyz="0 0 -1" />
    <limit
      lower="0"
      upper="0.35"
      effort="0"
      velocity="1.5"
    />
  </joint>
  
  <link
    name="link_3">
    <inertial>
      <origin
        xyz="0.0243635183551067 0.00114268549567356 0.0115268483183462"
        rpy="0 0 0" />
      <mass
        value="0.229071566881649" />
      <inertia
        ixx="0.000100353537549539"
        ixy="-6.54893775078155E-09"
        ixz="-1.17529230695251E-05"
        iyy="0.000132342607477726"
        iyz="-2.85679717502448E-08"
        izz="3.41547471223258E-05" />
    </inertial>
    <visual>
      <origin
        xyz="0 0 0"
        rpy="0 0 0" />
      <geometry>
        <mesh
          filename="package://xeno_urdf/xeno_urdf/meshes/link_3.STL" />
      </geometry>
      <material
        name="">
        <color
          rgba="0.898039215686275 0.917647058823529 0.929411764705882 1" />
      </material>
    </visual>
    <collision>
      <origin
        xyz="0 0 0"
        rpy="0 0 0" />
      <geometry>
        <mesh
          filename="package://xeno_urdf/xeno_urdf/meshes/link_3.STL" />
      </geometry>
    </collision>
  </link>
    <!-- 380mm -->
    <joint
    name="joint_3"
    type="prismatic">
    <origin
      xyz="-0.21627 0.03 -0.0436"
      rpy="0 -1.5708 3.1415" />
    <parent
      link="link_2" />
    <child
      link="link_3" />
    <axis
      xyz="0 0 1" />
    <limit
      lower="0"
      upper="0.17"
      effort="0"
      velocity="1.5"
    />
  </joint>

  <link
    name="link_4">
    <inertial>
      <origin
        xyz="0.00749547353516539 0.0253537500223402 -0.00500004630673573"
        rpy="0 0 0" />
      <mass
        value="0.477425970347628" />
      <inertia
        ixx="0.000187158341354507"
        ixy="-7.09558612423323E-06"
        ixz="-1.85555256049655E-06"
        iyy="0.000226324445424003"
        iyz="4.96022818756439E-06"
        izz="0.000186274577621382" />
    </inertial>
    <visual>
      <origin
        xyz="0 0 0"
        rpy="0 0 0" />
      <geometry>
        <mesh
          filename="package://xeno_urdf/xeno_urdf/meshes/link_4.STL" />
      </geometry>
      <material
        name="">
        <color
          rgba="0.25098 0.25098 0.25098 1" />
      </material>
    </visual>
    <collision>
      <origin
        xyz="0 0 0"
        rpy="0 0 0" />
      <geometry>
        <mesh
          filename="package://xeno_urdf/xeno_urdf/meshes/link_4.STL" />
      </geometry>
    </collision>
  </link>

  <joint
    name="joint_4"
    type="revolute">
    <origin
      xyz="0.0086 -0.023 -0.056"
      rpy="-3.1416 -1.0942 0" />
    <parent
      link="link_3" />
    <child
      link="link_4" />
    <axis
      xyz="0 1 0" />
    <limit
      lower="0"
      upper="3.14"
      effort="0"
      velocity="1.5"
    />
  </joint>

  <link
    name="link_5">
    <inertial>
      <origin
        xyz="-0.00224721059046937 0.0283490416869495 1.39038742325015E-10"
        rpy="0 0 0" />
      <mass
        value="0.326546716643345" />
      <inertia
        ixx="0.000132657862559401"
        ixy="4.61969466880693E-06"
        ixz="2.42597435500164E-09"
        iyy="0.000135875959468316"
        iyz="7.87145668063689E-14"
        izz="0.000122199670242012" />
    </inertial>
    <visual>
      <origin
        xyz="0 0 0"
        rpy="0 0 0" />
      <geometry>
        <mesh
          filename="package://xeno_urdf/xeno_urdf/meshes/link_5.STL" />
      </geometry>
      <material
        name="">
        <color
          rgba="0.250980392156863 0.250980392156863 0.250980392156863 1" />
      </material>
    </visual>
    <collision>
      <origin
        xyz="0 0 0"
        rpy="0 0 0" />
      <geometry>
        <mesh
          filename="package://xeno_urdf/xeno_urdf/meshes/link_5.STL" />
      </geometry>
    </collision>
  </link>

  <joint
    name="joint_5"
    type="revolute">
    <origin
      xyz="0.026992 0.017 -0.018102"
      rpy="-2.5508 0 1.5708" />
    <parent
      link="link_4" />
    <child
      link="link_5" />
    <axis
      xyz="0 1 0" />
    <limit
      lower="-3.14"
      upper="3.14"
      effort="0"
      velocity="1.5"
    />
  </joint>

  <link
    name="link_6">
    <inertial>
      <origin
        xyz="-0.0115040529308605 0.0242162714086535 0.0115427229561384"
        rpy="0 0 0" />
      <mass
        value="0.492715169362457" />
      <inertia
        ixx="0.00017384870013505"
        ixy="2.89812642925844E-07"
        ixz="5.5770997197448E-06"
        iyy="0.000210290903782881"
        iyz="1.05932333435736E-08"
        izz="0.00017448924482494" />
    </inertial>
    <visual>
      <origin
        xyz="0 0 0"
        rpy="0 0 0" />
      <geometry>
        <mesh
          filename="package://xeno_urdf/xeno_urdf/meshes/link_6.STL" />
      </geometry>
      <material
        name="">
        <color
          rgba="0.250980392156863 0.250980392156863 0.250980392156863 1" />
      </material>
    </visual>
    <collision>
      <origin
        xyz="0 0 0"
        rpy="0 0 0" />
      <geometry>
        <mesh
          filename="package://xeno_urdf/xeno_urdf/meshes/link_6.STL" />
      </geometry>
    </collision>
  </link>

  <joint
    name="joint_6"
    type="revolute">
    <origin
      xyz="-0.017 0.087 0"
      rpy="0 -0.7883 -1.5708" />
    <parent
      link="link_5" />
    <child
      link="link_6" />
    <axis
      xyz="0 1 0" />
    <limit
      lower="-3.14"
      upper="3.14"
      effort="0"
      velocity="1.5"
    />
  </joint>

  <link
    name="link_7">
    <inertial>
      <origin
        xyz="-0.00884716771498142 4.09347072904964E-09 1.11903771249366E-08"
        rpy="0 0 0" />
      <mass
        value="0.0441931131241814" />
      <inertia
        ixx="1.86781683229587E-05"
        ixy="-3.22043201807127E-12"
        ixz="-3.36854010482971E-12"
        iyy="1.15856573921313E-05"
        iyz="-7.70011465201016E-12"
        izz="1.15856654956983E-05" />
    </inertial>
    <visual>
      <origin
        xyz="0 0 0"
        rpy="0 0 0" />
      <geometry>
        <mesh
          filename="package://xeno_urdf/xeno_urdf/meshes/link_7.STL" />
      </geometry>
      <material
        name="">
        <color
          rgba="0 0 0 0.5" />
      </material>
    </visual>
    <collision>
      <origin
        xyz="0 0 0"
        rpy="0 0 0" />
      <geometry>
        <mesh
          filename="package://xeno_urdf/xeno_urdf/meshes/link_7.STL" />
      </geometry>
    </collision>
  </link>

  <joint
    name="joint_7"
    type="continuous">
    <origin
      xyz="-0.077075 0.033 0.077075"
      rpy="0.89704 0.7854 0" />
    <parent
      link="link_6" />
    <child
      link="link_7" />
    <axis
      xyz="-1 0 0" />
    <limit
      lower="0"
      upper="0"
      effort="0"
      velocity="1.5"
    />
  </joint>
  

</robot>