<?xml version="1.0"?>
<robot xmlns:xacro="http://www.ros.org/wiki/xacro" name="xeno_urdf">

  <link
    name="base_link">
    <inertial>
      <origin
        xyz="0.26669695579372 -0.242025752926975 0.0430843772309064"
        rpy="0 0 0" />
      <mass
        value="2.67946025521633" />
      <inertia
        ixx="0.0247505610420922"
        ixy="1.20986595669565E-08"
        ixz="3.25666768339599E-05"
        iyy="0.0352698053676739"
        iyz="1.26675265404138E-09"
        izz="0.0311353357370667" />
    </inertial>
    <visual>
      <origin
        xyz="0 0 0"
        rpy="0 0 0" />
      <geometry>
        <mesh
          filename="package://xeno_urdf/xeno_urdf/meshes/base_link.STL" />
      </geometry>
      <material
        name="">
        <color
          rgba="0.792156862745098 0.819607843137255 0.933333333333333 1" />
      </material>
    </visual>
    <collision>
      <origin
        xyz="0 0 0"
        rpy="0 0 0" />
      <geometry>
        <mesh
          filename="package://xeno_urdf/xeno_urdf/meshes/base_link.STL" />
      </geometry>
    </collision>
  </link>

  <link
    name="link_1">
    <inertial>
      <origin
        xyz="0.185028595714662 -0.00832277412155959 -0.178922873353644"
        rpy="0 0 0" />
      <mass
        value="0.331227493236693" />
      <inertia
        ixx="0.00359557900980095"
        ixy="8.1925548172336E-13"
        ixz="4.10157129333264E-18"
        iyy="0.00357618701291859"
        iyz="6.09931701507021E-18"
        izz="6.20714942709694E-05" />
    </inertial>
    <visual>
      <origin
        xyz="0 0 0"
        rpy="0 0 0" />
      <geometry>
        <mesh
          filename="package://xeno_urdf/xeno_urdf/meshes/link1.STL" />
      </geometry>
      <material
        name="">
        <color
          rgba="0.792156862745098 0.819607843137255 0.933333333333333 1" />
      </material>
    </visual>
    <collision>
      <origin
        xyz="0 0 0"
        rpy="0 0 0" />
      <geometry>
        <mesh
          filename="package://xeno_urdf/xeno_urdf/meshes/link1.STL" />
      </geometry>
    </collision>
  </link>

  <joint
    name="joint_1"
    type="prismatic">
    <origin
      xyz="0.067202 -0.055049 0.04839"
      rpy="1.5708 0 -1.5708" />
    <parent
      link="base_link" />
    <child
      link="link_1" />
    <axis
      xyz="0 1 0" />
    <limit
      lower="-0.32"
      upper="0.32"
      effort="0"
      velocity="1.5" />
  </joint>

  <link
    name="link_2">
    <inertial>
      <origin
        xyz="-0.147952953542361 0.00721513789627723 0.11139952012947"
        rpy="0 0 0" />
      <mass
        value="1.13992890911822" />
      <inertia
        ixx="0.0083301452591185"
        ixy="8.60827876876126E-09"
        ixz="1.75396040690603E-06"
        iyy="0.0142979811659756"
        iyz="-8.55343268612929E-07"
        izz="0.00606948576919771" />
    </inertial>
    <visual>
      <origin
        xyz="0 0 0"
        rpy="0 0 0" />
      <geometry>
        <mesh
          filename="package://xeno_urdf/xeno_urdf/meshes/link2.STL" />
      </geometry>
      <material
        name="">
        <color
          rgba="0.792156862745098 0.819607843137255 0.933333333333333 1" />
      </material>
    </visual>
    <collision>
      <origin
        xyz="0 0 0"
        rpy="0 0 0" />
      <geometry>
        <mesh
          filename="package://xeno_urdf/xeno_urdf/meshes/link2.STL" />
      </geometry>
    </collision>
  </link>

  <joint
    name="joint_2"
    type="prismatic">
    <origin
      xyz="0.034 2.4196E-05 0.019096"
      rpy="-3.141 0 3.1416" />
    <parent
      link="link_1" />
    <child
      link="link_2" />
    <axis
      xyz="0 0 -1" />
    <limit
      lower="-0.35"
      upper="0.35"
      effort="0"
      velocity="1.5"
    />
  </joint>

  <link
    name="link_3">
    <inertial>
      <origin
        xyz="0.0232065797639486 0.00113688050742744 0.0100412795305758"
        rpy="0 0 0" />
      <mass
        value="0.241891764846693" />
      <inertia
        ixx="0.000103123442652323"
        ixy="-6.54893775078498E-09"
        ixz="-1.17529230695251E-05"
        iyy="0.000137114148084955"
        iyz="-2.85679717502139E-08"
        izz="3.61873133027448E-05" />
    </inertial>
    <visual>
      <origin
        xyz="0 0 0"
        rpy="0 0 0" />
      <geometry>
        <mesh
          filename="package://xeno_urdf/xeno_urdf/meshes/link3.STL" />
      </geometry>
      <material
        name="">
        <color
          rgba="0.898039215686275 0.917647058823529 0.929411764705882 1" />
      </material>
    </visual>
    <collision>
      <origin
        xyz="0 0 0"
        rpy="0 0 0" />
      <geometry>
        <mesh
          filename="package://xeno_urdf/xeno_urdf/meshes/link3.STL" />
      </geometry>
    </collision>
  </link>

    <joint
    name="joint_3"
    type="prismatic">
    <origin
      xyz="-0.21627 0.03 -0.0436"
      rpy="0 -1.5708 3.1415" />
    <parent
      link="link_2" />
    <child
      link="link_3" />
    <axis
      xyz="0 0 -1" />
    <limit
      lower="-0.38"
      upper="0.38"
      effort="0"
      velocity="1.5"
    />
  </joint>

  <link
    name="link_4">
    <inertial>
      <origin
        xyz="0.0075553 0.025636 -0.0050399"
        rpy="0 0 0" />
      <mass
        value="0.47365" />
      <inertia
        ixx="0.00018548"
        ixy="-7.0956E-06"
        ixz="-1.8556E-06"
        iyy="0.00022296"
        iyz="4.9602E-06"
        izz="0.00018459" />
    </inertial>
    <visual>
      <origin
        xyz="0 0 0"
        rpy="0 0 0" />
      <geometry>
        <mesh
          filename="package://xeno_urdf/xeno_urdf/meshes/link4.STL" />
      </geometry>
      <material
        name="">
        <color
          rgba="0.25098 0.25098 0.25098 1" />
      </material>
    </visual>
    <collision>
      <origin
        xyz="0 0 0"
        rpy="0 0 0" />
      <geometry>
        <mesh
          filename="package://xeno_urdf/xeno_urdf/meshes/link4.STL" />
      </geometry>
    </collision>
  </link>

  <joint
    name="joint_4"
    type="revolute">
    <origin
      xyz="0.0086 -0.023 -0.056"
      rpy="-3.1416 -1.0942 0" />
    <parent
      link="link_3" />
    <child
      link="link_4" />
    <axis
      xyz="0 1 0" />
    <limit
      lower="0"
      upper="3.14"
      effort="0"
      velocity="1.5"
    />
  </joint>

  <link
    name="link_5">
    <inertial>
      <origin
        xyz="-0.0022472 0.028349 1.3904E-10"
        rpy="0 0 0" />
      <mass
        value="0.32655" />
      <inertia
        ixx="0.00013266"
        ixy="4.6197E-06"
        ixz="2.426E-09"
        iyy="0.00013588"
        iyz="7.8715E-14"
        izz="0.0001222" />
    </inertial>
    <visual>
      <origin
        xyz="0 0 0"
        rpy="0 0 0" />
      <geometry>
        <mesh
          filename="package://xeno_urdf/xeno_urdf/meshes/link5.STL" />
      </geometry>
      <material
        name="">
        <color
          rgba="0.250980392156863 0.250980392156863 0.250980392156863 1" />
      </material>
    </visual>
    <collision>
      <origin
        xyz="0 0 0"
        rpy="0 0 0" />
      <geometry>
        <mesh
          filename="package://xeno_urdf/xeno_urdf/meshes/link5.STL" />
      </geometry>
    </collision>
  </link>

  <joint
    name="joint_5"
    type="revolute">
    <origin
      xyz="0.026992 0.017 -0.018102"
      rpy="-2.5508 0 1.5708" />
    <parent
      link="link_4" />
    <child
      link="link_5" />
    <axis
      xyz="0 1 0" />
    <limit
      lower="-3.14"
      upper="3.14"
      effort="0"
      velocity="1.5"
    />
  </joint>

  <link
    name="link_6">
    <inertial>
      <origin
        xyz="-0.011521 0.021899 0.012318"
        rpy="0 0 0" />
      <mass
        value="0.51621" />
      <inertia
        ixx="0.00019251"
        ixy="2.8892E-07"
        ixz="1.8201E-05"
        iyy="0.00025598"
        iyz="1.1486E-08"
        izz="0.00019315" />
    </inertial>
    <visual>
      <origin
        xyz="0 0 0"
        rpy="0 0 0" />
      <geometry>
        <mesh
          filename="package://xeno_urdf/xeno_urdf/meshes/link6.STL" />
      </geometry>
      <material
        name="">
        <color
          rgba="0.250980392156863 0.250980392156863 0.250980392156863 1" />
      </material>
    </visual>
    <collision>
      <origin
        xyz="0 0 0"
        rpy="0 0 0" />
      <geometry>
        <mesh
          filename="package://xeno_urdf/xeno_urdf/meshes/link6.STL" />
      </geometry>
    </collision>
  </link>

  <joint
    name="joint_6"
    type="revolute">
    <origin
      xyz="-0.017 0.087 0"
      rpy="0 -0.7883 -1.5708" />
    <parent
      link="link_5" />
    <child
      link="link_6" />
    <axis
      xyz="0 1 0" />
    <limit
      lower="-3.14"
      upper="3.14"
      effort="0"
      velocity="1.5"
    />
  </joint>

  <link
    name="link_7">
    <inertial>
      <origin
        xyz="-0.0088472 4.0935E-09 1.119E-08"
        rpy="0 0 0" />
      <mass
        value="0.044193" />
      <inertia
        ixx="1.8678E-05"
        ixy="-3.2204E-12"
        ixz="-3.3685E-12"
        iyy="1.1586E-05"
        iyz="-7.7001E-12"
        izz="1.1586E-05" />
    </inertial>
    <visual>
      <origin
        xyz="0 0 0"
        rpy="0 0 0" />
      <geometry>
        <mesh
          filename="package://xeno_urdf/xeno_urdf/meshes/link7.STL" />
      </geometry>
      <material
        name="">
        <color
          rgba="0 0 0 1" />
      </material>
    </visual>
    <collision>
      <origin
        xyz="0 0 0"
        rpy="0 0 0" />
      <geometry>
        <mesh
          filename="package://xeno_urdf/xeno_urdf/meshes/link6.STL" />
      </geometry>
    </collision>
  </link>

  <joint
    name="joint_7"
    type="revolute">
    <origin
      xyz="-0.077075 0.033 0.077075"
      rpy="0.89704 0.7854 0" />
    <parent
      link="link_6" />
    <child
      link="link_7" />
    <axis
      xyz="-1 0 0" />
    <limit
      lower="-3.14"
      upper="3.14"
      effort="0"
      velocity="1.5"
    />
  </joint>
  

</robot>